<?xml version="1.0" ?>
<!-- =================================================================================== -->
<!-- |    This document was autogenerated by xacro from amr.urdf.xacro                 | -->
<!-- |    EDITING THIS FILE BY HAND IS NOT RECOMMENDED                                 | -->
<!-- =================================================================================== -->
<robot name="amr">
  <gazebo reference="base_link">
    <material>Gazebo/Blue</material>
  </gazebo>
  <!-- 
  <gazebo>
    <plugin filename="libgazebo_ros_diff_drive.so" name="amr_controller">
      <commandTopic>cmd_vel</commandTopic>
      <odometryTopic>odom_gazebo</odometryTopic>
      <odometryFrame>odom_gazebo</odometryFrame>
      <odometrySource>world</odometrySource>
      <publishOdomTF>false</publishOdomTF>
      <robotBaseFrame>base_link</robotBaseFrame>
      <publishWheelTF>false</publishWheelTF>
      <publishTf>true</publishTf>
      <publishWheelJointState>true</publishWheelJointState>
      <legacyMode>false</legacyMode>
      <updateRate>30</updateRate>
      <leftJoint>lw_joint</leftJoint>
      <rightJoint>rw_joint</rightJoint>
      <wheelSeparation>0.4</wheelSeparation>
      <wheelDiameter>0.2</wheelDiameter>
      <wheelAcceleration>1</wheelAcceleration>
      <wheelTorque>10</wheelTorque>
      <rosDebugLevel>na</rosDebugLevel>
    </plugin>
  </gazebo>
  -->
  <gazebo>
    <plugin filename="libgazebo_ros_diff_drive.so" name="differential_drive_controller">
      <alwaysOn>true</alwaysOn>
      <updateRate>100</updateRate>
      <leftJoint>lw_joint</leftJoint>
      <rightJoint>rw_joint</rightJoint>
      <wheelSeparation>0.5380</wheelSeparation>
      <wheelDiameter>0.2410</wheelDiameter>
      <torque>20</torque>
      <commandTopic>cmd_vel</commandTopic>
      <odometryTopic>odom/unfiltered</odometryTopic>
      <odometryFrame>odom</odometryFrame>
      <robotBaseFrame>base_link</robotBaseFrame>
      <legacyMode>false</legacyMode>
    </plugin>
  </gazebo>
  <!-- hokuyo -->
  <gazebo reference="hokuyo_link">
    <sensor name="head_hokuyo_sensor" type="ray">
      <pose>0 0 0 0 0 0</pose>
      <visualize>true</visualize>
      <update_rate>40</update_rate>
      <ray>
        <scan>
          <horizontal>
            <samples>1080</samples>
            <resolution>1</resolution>
            <min_angle>-2.35619</min_angle>
            <max_angle>2.35619</max_angle>
          </horizontal>
        </scan>
        <range>
          <min>0.10</min>
          <max>30.0</max>
          <resolution>0.01</resolution>
        </range>
        <noise>
          <type>gaussian</type>
          <!-- Noise parameters based on published spec for Hokuyo laser
               achieving "+-30mm" accuracy at range < 10m.  A mean of 0.0m and
               stddev of 0.01m will put 99.7% of samples within 0.03m of the true
               reading. -->
          <mean>0.0</mean>
          <stddev>0.02</stddev>
        </noise>
      </ray>
      <plugin filename="libgazebo_ros_laser.so" name="gazebo_ros_head_hokuyo_controller">
        <topicName>/scan</topicName>
        <frameName>hokuyo_link</frameName>
      </plugin>
    </sensor>
  </gazebo>
  <link name="base_link">
    <inertial>
      <origin rpy="0 0 0" xyz="0.000331566894459373 -1.38869584628603E-18 0.0226798732825691"/>
      <mass value="16.6607693249907"/>
      <inertia ixx="0.342900416454384" ixy="-0.00791208000000003" ixz="-4.11696589312513E-05" iyy="0.595999267514538" iyz="-2.06655190930544E-17" izz="0.933088946009388"/>
    </inertial>
    <visual>
      <origin rpy="0 0 0" xyz="0 0 0"/>
      <geometry>
        <mesh filename="package://amr_description/meshes/base_link.STL"/>
      </geometry>
      <material name="">
        <color rgba="0.898039215686275 0.917647058823529 0.929411764705882 1"/>
      </material>
    </visual>
    <collision>
      <origin rpy="0 0 0" xyz="0 0 0"/>
      <geometry>
        <mesh filename="package://amr_description/meshes/base_link.STL"/>
      </geometry>
    </collision>
  </link>
  <link name="lw_link">
    <inertial>
      <origin rpy="0 0 0" xyz="1.90819582357449E-17 0 -0.0273880597014926"/>
      <mass value="1.34185276216454"/>
      <inertia ixx="0.00397939442139444" ixy="-2.16840434497101E-19" ixz="-5.79710388341049E-20" iyy="0.00397939442139444" iyz="1.23940974937118E-21" izz="0.00747907672941523"/>
    </inertial>
    <visual>
      <origin rpy="0 0 0" xyz="0 0 0"/>
      <geometry>
        <mesh filename="package://amr_description/meshes/lw_link.STL"/>
      </geometry>
      <material name="">
        <color rgba="1 1 1 1"/>
      </material>
    </visual>
    <collision>
      <origin rpy="0 0 0" xyz="0 0 0"/>
      <geometry>
        <mesh filename="package://amr_description/meshes/lw_link.STL"/>
      </geometry>
    </collision>
  </link>
  <joint name="lw_joint" type="continuous">
    <origin rpy="-1.5707963267949 0.273855441267016 3.14159265358979" xyz="0 0.26 0.055"/>
    <parent link="base_link"/>
    <child link="lw_link"/>
    <axis xyz="0 0 -1"/>
    <safety_controller k_velocity="0"/>
  </joint>
  <link name="rw_link">
    <inertial>
      <origin rpy="0 0 0" xyz="1.1106354187428E-17 0 -0.0273880597014926"/>
      <mass value="1.34185276216454"/>
      <inertia ixx="0.00397939442139445" ixy="-3.23472618749719E-35" ixz="-1.8026519749501E-21" iyy="0.00397939442139445" iyz="-1.7985063567581E-35" izz="0.00747907672941523"/>
    </inertial>
    <visual>
      <origin rpy="0 0 0" xyz="0 0 0"/>
      <geometry>
        <mesh filename="package://amr_description/meshes/rw_link.STL"/>
      </geometry>
      <material name="">
        <color rgba="1 1 1 1"/>
      </material>
    </visual>
    <collision>
      <origin rpy="0 0 0" xyz="0 0 0"/>
      <geometry>
        <mesh filename="package://amr_description/meshes/rw_link.STL"/>
      </geometry>
    </collision>
  </link>
  <joint name="rw_joint" type="continuous">
    <origin rpy="1.5707963267949 0 3.14159265358979" xyz="0 -0.26 0.055"/>
    <parent link="base_link"/>
    <child link="rw_link"/>
    <axis xyz="0 0 1"/>
    <safety_controller k_velocity="0"/>
  </joint>
  <link name="flc_link">
    <inertial>
      <origin rpy="0 0 0" xyz="0 -0.0104639072674438 0"/>
      <mass value="0.00737117883440488"/>
      <inertia ixx="1.43643640511466E-06" ixy="-9.24994132532978E-23" ixz="0" iyy="1.26133689808569E-07" iyz="3.92477458277648E-23" izz="1.4200125484889E-06"/>
    </inertial>
    <visual>
      <origin rpy="0 0 0" xyz="0 0 0"/>
      <geometry>
        <mesh filename="package://amr_description/meshes/flc_link.STL"/>
      </geometry>
      <material name="">
        <color rgba="0.898039215686275 0.917647058823529 0.929411764705882 1"/>
      </material>
    </visual>
    <collision>
      <origin rpy="0 0 0" xyz="0 0 0"/>
      <geometry>
        <mesh filename="package://amr_description/meshes/flc_link.STL"/>
      </geometry>
    </collision>
  </link>
  <joint name="flc_joint" type="continuous">
    <origin rpy="1.5707963267949 0 0.302678309023654" xyz="0.325 0.15 0"/>
    <parent link="base_link"/>
    <child link="flc_link"/>
    <axis xyz="0 1 0"/>
    <safety_controller k_velocity="0"/>
  </joint>
  <link name="flw_link">
    <inertial>
      <origin rpy="0 0 0" xyz="-5.55111512312578E-17 0 2.77555756156289E-17"/>
      <mass value="0.00384530940799391"/>
      <inertia ixx="2.51867766223601E-07" ixy="-4.58926493494391E-41" ixz="-4.63221143029696E-23" iyy="2.51867766223601E-07" iyz="-4.17990250274816E-40" izz="4.80663675999238E-07"/>
    </inertial>
    <visual>
      <origin rpy="0 0 0" xyz="0 0 0"/>
      <geometry>
        <mesh filename="package://amr_description/meshes/flw_link.STL"/>
      </geometry>
      <material name="">
        <color rgba="1 1 1 1"/>
      </material>
    </visual>
    <collision>
      <origin rpy="0 0 0" xyz="0 0 0"/>
      <geometry>
        <mesh filename="package://amr_description/meshes/flw_link.STL"/>
      </geometry>
    </collision>
  </link>
  <joint name="flw_joint" type="continuous">
    <origin rpy="3.14159265358979 0 3.14159265358979" xyz="0 -0.03 0"/>
    <parent link="flc_link"/>
    <child link="flw_link"/>
    <axis xyz="0 0 1"/>
    <safety_controller k_velocity="0"/>
  </joint>
  <link name="frc_link">
    <inertial>
      <origin rpy="0 0 0" xyz="0 -0.0104639072674438 -5.55111512312578E-17"/>
      <mass value="0.00737117883440488"/>
      <inertia ixx="1.43643640511466E-06" ixy="-9.4508637668121E-23" ixz="0" iyy="1.26133689808569E-07" iyz="4.2023419920401E-23" izz="1.4200125484889E-06"/>
    </inertial>
    <visual>
      <origin rpy="0 0 0" xyz="0 0 0"/>
      <geometry>
        <mesh filename="package://amr_description/meshes/frc_link.STL"/>
      </geometry>
      <material name="">
        <color rgba="0.898039215686275 0.917647058823529 0.929411764705882 1"/>
      </material>
    </visual>
    <collision>
      <origin rpy="0 0 0" xyz="0 0 0"/>
      <geometry>
        <mesh filename="package://amr_description/meshes/frc_link.STL"/>
      </geometry>
    </collision>
  </link>
  <joint name="frc_joint" type="continuous">
    <origin rpy="1.5707963267949 0 0.302678309023654" xyz="0.325 -0.15 0"/>
    <parent link="base_link"/>
    <child link="frc_link"/>
    <axis xyz="0 1 0"/>
    <safety_controller k_velocity="0"/>
  </joint>
  <link name="frw_link">
    <inertial>
      <origin rpy="0 0 0" xyz="0 0 5.55111512312578E-17"/>
      <mass value="0.00384530940799391"/>
      <inertia ixx="2.51867766223601E-07" ixy="-4.58926493494544E-41" ixz="-4.63221143029696E-23" iyy="2.51867766223601E-07" iyz="-4.17990250274816E-40" izz="4.80663675999238E-07"/>
    </inertial>
    <visual>
      <origin rpy="0 0 0" xyz="0 0 0"/>
      <geometry>
        <mesh filename="package://amr_description/meshes/frw_link.STL"/>
      </geometry>
      <material name="">
        <color rgba="1 1 1 1"/>
      </material>
    </visual>
    <collision>
      <origin rpy="0 0 0" xyz="0 0 0"/>
      <geometry>
        <mesh filename="package://amr_description/meshes/frw_link.STL"/>
      </geometry>
    </collision>
  </link>
  <joint name="frw_joint" type="continuous">
    <origin rpy="3.14159265358979 0 3.14159265358979" xyz="0 -0.03 0"/>
    <parent link="frc_link"/>
    <child link="frw_link"/>
    <axis xyz="0 0 1"/>
    <safety_controller k_velocity="0"/>
  </joint>
  <link name="rlc_link">
    <inertial>
      <origin rpy="0 0 0" xyz="0 -0.0104639072674438 2.77555756156289E-17"/>
      <mass value="0.0073711788344049"/>
      <inertia ixx="1.43643640511466E-06" ixy="-1.01781597610719E-21" ixz="-1.58818677610181E-22" iyy="1.2613368980857E-07" iyz="-2.21052017608903E-22" izz="1.42001254848891E-06"/>
    </inertial>
    <visual>
      <origin rpy="0 0 0" xyz="0 0 0"/>
      <geometry>
        <mesh filename="package://amr_description/meshes/rlc_link.STL"/>
      </geometry>
      <material name="">
        <color rgba="0.898039215686275 0.917647058823529 0.929411764705882 1"/>
      </material>
    </visual>
    <collision>
      <origin rpy="0 0 0" xyz="0 0 0"/>
      <geometry>
        <mesh filename="package://amr_description/meshes/rlc_link.STL"/>
      </geometry>
    </collision>
  </link>
  <joint name="rlc_joint" type="continuous">
    <origin rpy="1.5707963267949 0 -1.03857643916073" xyz="-0.325 0.15 0"/>
    <parent link="base_link"/>
    <child link="rlc_link"/>
    <axis xyz="0 1 0"/>
    <safety_controller k_velocity="0"/>
  </joint>
  <link name="rlw_link">
    <inertial>
      <origin rpy="0 0 0" xyz="5.55111512312578E-17 2.77555756156289E-17 5.55111512312578E-17"/>
      <mass value="0.00384530940799391"/>
      <inertia ixx="2.51867766223601E-07" ixy="5.29395592033938E-23" ixz="3.37489689921635E-22" iyy="2.51867766223601E-07" iyz="2.84550130718242E-22" izz="4.80663675999239E-07"/>
    </inertial>
    <visual>
      <origin rpy="0 0 0" xyz="0 0 0"/>
      <geometry>
        <mesh filename="package://amr_description/meshes/rlw_link.STL"/>
      </geometry>
      <material name="">
        <color rgba="1 1 1 1"/>
      </material>
    </visual>
    <collision>
      <origin rpy="0 0 0" xyz="0 0 0"/>
      <geometry>
        <mesh filename="package://amr_description/meshes/rlw_link.STL"/>
      </geometry>
    </collision>
  </link>
  <joint name="rlw_joint" type="continuous">
    <origin rpy="-3.14159265358979 0 0.637762511071717" xyz="0 -0.0300000000000003 0"/>
    <parent link="rlc_link"/>
    <child link="rlw_link"/>
    <axis xyz="0 0 1"/>
    <safety_controller k_velocity="0"/>
  </joint>
  <link name="rrc_link">
    <inertial>
      <origin rpy="0 0 0" xyz="0 -0.0104639072674438 0"/>
      <mass value="0.00737117883440487"/>
      <inertia ixx="1.43643640511466E-06" ixy="-3.97763393383722E-22" ixz="1.58818677610181E-22" iyy="1.26133689808569E-07" iyz="-1.05058384208789E-22" izz="1.4200125484889E-06"/>
    </inertial>
    <visual>
      <origin rpy="0 0 0" xyz="0 0 0"/>
      <geometry>
        <mesh filename="package://amr_description/meshes/rrc_link.STL"/>
      </geometry>
      <material name="">
        <color rgba="0.898039215686275 0.917647058823529 0.929411764705882 1"/>
      </material>
    </visual>
    <collision>
      <origin rpy="0 0 0" xyz="0 0 0"/>
      <geometry>
        <mesh filename="package://amr_description/meshes/rrc_link.STL"/>
      </geometry>
    </collision>
  </link>
  <joint name="rrc_joint" type="continuous">
    <origin rpy="1.5707963267949 0 -2.04580309292895" xyz="-0.324999999999998 -0.15 0"/>
    <parent link="base_link"/>
    <child link="rrc_link"/>
    <axis xyz="0 1 0"/>
    <safety_controller k_velocity="0"/>
  </joint>
  <link name="rrw_link">
    <inertial>
      <origin rpy="0 0 0" xyz="-5.55111512312578E-17 1.05124242644195E-15 2.77555756156289E-17"/>
      <mass value="0.00384530940799392"/>
      <inertia ixx="2.51867766223602E-07" ixy="-4.96308367531817E-24" ixz="-7.94093388050907E-23" iyy="2.51867766223602E-07" iyz="4.17726209339279E-22" izz="4.8066367599924E-07"/>
    </inertial>
    <visual>
      <origin rpy="0 0 0" xyz="0 0 0"/>
      <geometry>
        <mesh filename="package://amr_description/meshes/rrw_link.STL"/>
      </geometry>
      <material name="">
        <color rgba="1 1 1 1"/>
      </material>
    </visual>
    <collision>
      <origin rpy="0 0 0" xyz="0 0 0"/>
      <geometry>
        <mesh filename="package://amr_description/meshes/rrw_link.STL"/>
      </geometry>
    </collision>
  </link>
  <joint name="rrw_joint" type="continuous">
    <origin rpy="0 0 -0.13755116916335" xyz="0 -0.03 0"/>
    <parent link="rrc_link"/>
    <child link="rrw_link"/>
    <axis xyz="0 0 1"/>
    <safety_controller k_velocity="0"/>
  </joint>
  <joint name="hokuyo_joint" type="fixed">
    <origin rpy="0 0 0.7853" xyz="0.40 0.25 0.2"/>
    <parent link="base_link"/>
    <child link="hokuyo_link"/>
  </joint>
  <link name="hokuyo_link">
    <visual>
      <origin rpy="0 0 0" xyz="0 0 0"/>
      <geometry>
        <mesh filename="model://hokuyo/meshes/hokuyo.dae"/>
      </geometry>
    </visual>
    <collision>
      <origin rpy="0 0 0" xyz="0 0 0"/>
      <geometry>
        <mesh filename="model://hokuyo/meshes/hokuyo.dae"/>
      </geometry>
    </collision>
  </link>
</robot>
